<?xml version="1.0"?>
<robot name="lolo_auv" xmlns:xacro="http://www.ros.org/wiki/xacro">

  <xacro:property name="visual_mesh_file" value="file://$(find lolo_description)/mesh/lolo_hull.dae"/>
  <xacro:property name="prop_port_mesh_file" value="file://$(find lolo_description)/mesh/lolo_port_propeller.dae"/>
  <xacro:property name="prop_strb_mesh_file" value="file://$(find lolo_description)/mesh/lolo_strb_propeller.dae"/>
  <xacro:property name="rudder_mesh_file" value="file://$(find lolo_description)/mesh/lolo_rudder.dae"/>
  <xacro:property name="elevon_port_mesh_file" value="file://$(find lolo_description)/mesh/lolo_port_elevon.dae"/>
  <xacro:property name="elevon_strb_mesh_file" value="file://$(find lolo_description)/mesh/lolo_strb_elevon.dae"/>
  <xacro:property name="elevator_mesh_file" value="file://$(find lolo_description)/mesh/lolo_elevator.dae"/>

  <link name="$(arg robot_namespace)/base_link">
    <visual>
      <origin xyz="0 0 0" rpy="0 0 0"/>
      <geometry>
        <mesh filename="${visual_mesh_file}" scale="1 1 1" />
      </geometry>
    </visual>
  </link>

  <link name="$(arg robot_namespace)/dvl_link"/>
  <link name="$(arg robot_namespace)/compass_link"/>
  <link name="$(arg robot_namespace)/fls_link"/>
  <link name="$(arg robot_namespace)/imu_link"/>
  <link name="$(arg robot_namespace)/pressure_link"/>
  <link name="$(arg robot_namespace)/gps_link"/>
  <link name="$(arg robot_namespace)/mbes_link"/>
  <link name="$(arg robot_namespace)/usbl_link"/>

  <link name="$(arg robot_namespace)/elevator">
    <visual>
      <origin xyz="0 0 0" rpy="0 0 0" />
      <geometry>
        <mesh filename="${elevator_mesh_file}" scale="1 1 1"/>
      </geometry>
    </visual>
  </link>

  <link name="$(arg robot_namespace)/rudder_stbd">
    <visual>
      <origin xyz="0 0 0" rpy="0 0 0" />
      <geometry>
        <mesh filename="${rudder_mesh_file}" scale="1 1 1"/>
      </geometry>
    </visual>
  </link>

  <link name="$(arg robot_namespace)/rudder_port">
    <visual>
      <origin xyz="0 0 0" rpy="0 0 0" />
      <geometry>
        <mesh filename="${rudder_mesh_file}" scale="1 1 1"/>
      </geometry>
    </visual>
  </link>

  <link name="$(arg robot_namespace)/elevon_stbd">
    <visual>
      <origin xyz="0 0 0" rpy="0 0 0" />
      <geometry>
        <mesh filename="${elevon_strb_mesh_file}" scale="1 1 1"/>
      </geometry>
    </visual>
  </link>

  <link name="$(arg robot_namespace)/elevon_port">
    <visual>
      <origin xyz="0 0 0" rpy="0 0 0" />
      <geometry>
        <mesh filename="${elevon_port_mesh_file}" scale="1 1 1"/>
      </geometry>
    </visual>
  </link>

  <link name="$(arg robot_namespace)/thruster_port">
    <visual>
      <origin xyz="0.0 0 0" rpy="0 0 0" />
      <geometry>
        <mesh filename="${prop_port_mesh_file}" scale="1 1 1"/>
      </geometry>
    </visual>
  </link>

  <link name="$(arg robot_namespace)/thruster_stbd">
    <visual>
      <origin xyz="0.0 0 0" rpy="0 0 0" />
      <geometry>
        <mesh filename="${prop_strb_mesh_file}" scale="1 1 1"/>
      </geometry>
    </visual>
  </link>

  <!-- Mount a 3D pose sensor -->
  <link name="$(arg robot_namespace)/pose_sensor_link">
    <visual>
      <geometry>
        <box size="0.01 0.01 0.01" />
      </geometry>
    </visual>
  </link>

  <joint name="$(arg robot_namespace)/elevator_joint" type="revolute">
    <origin xyz="-0.6476 0.0 0.0135" rpy="0 0 0" />
    <parent link="$(arg robot_namespace)/base_link" />
    <child link="$(arg robot_namespace)/elevator" />
    <limit effort="0" lower="-${pi/4.0}" upper="${pi/4.0}" velocity="0"/>
    <axis xyz="0 1 0"/>
  </joint>

  <joint name="$(arg robot_namespace)/rudder_stbd_joint" type="revolute">
    <origin xyz="-0.3278 -0.253 0.129" rpy="0 0 0" />
    <parent link="$(arg robot_namespace)/base_link" />
    <child link="$(arg robot_namespace)/rudder_stbd" />
    <limit effort="0" lower="-${pi/4.0}" upper="${pi/4.0}" velocity="0"/>
    <axis xyz="0 0 1"/>
  </joint>

  <joint name="$(arg robot_namespace)/rudder_port_joint" type="revolute">
    <origin xyz="-0.3278 0.253 0.129" rpy="0 0 0" />
    <parent link="$(arg robot_namespace)/base_link" />
    <child link="$(arg robot_namespace)/rudder_port" />
    <limit effort="0" lower="-${pi/4.0}" upper="${pi/4.0}" velocity="0"/>
    <axis xyz="0 0 1"/>
  </joint>

  <joint name="$(arg robot_namespace)/elevon_stbd_joint" type="revolute">
    <origin xyz="-0.3733 -0.4035 0.01349" rpy="0 0 -0.19652" />
    <parent link="$(arg robot_namespace)/base_link" />
    <child link="$(arg robot_namespace)/elevon_stbd" />
    <limit effort="0" lower="-${pi/4.0}" upper="${pi/4.0}" velocity="0"/>
    <axis xyz="0 1 0"/>
  </joint>

  <joint name="$(arg robot_namespace)/elevon_port_joint" type="revolute">
    <origin xyz="-0.3733 0.4035 0.01349" rpy="0 0 0.19652" />
    <parent link="$(arg robot_namespace)/base_link" />
    <child link="$(arg robot_namespace)/elevon_port" />
    <limit effort="0" lower="-${pi/4.0}" upper="${pi/4.0}" velocity="0"/>
    <axis xyz="0 1 0"/>
  </joint>

  <!-- Propeller -->
  <joint name="$(arg robot_namespace)/thruster_stbd_joint" type="continuous">
    <origin xyz="-0.9056 -0.2754 0.013678" rpy="0 0 0" />
    <axis xyz="1 0 0"/>
    <parent link="$(arg robot_namespace)/base_link"/>
    <child link="$(arg robot_namespace)/thruster_stbd"/>
  </joint>

  <joint name="$(arg robot_namespace)/thruster_port_joint" type="continuous">
    <origin xyz="-0.9056 0.2754 0.013678" rpy="0 0 0" />
    <axis xyz="1 0 0"/>
    <parent link="$(arg robot_namespace)/base_link"/>
    <child link="$(arg robot_namespace)/thruster_port"/>
  </joint>

  <joint name="$(arg robot_namespace)/pose_sensor_joint" type="revolute">
    <origin xyz="0 0 0" rpy="0 0 0" />
    <parent link="$(arg robot_namespace)/base_link"/>
    <child link="$(arg robot_namespace)/pose_sensor_link"/>
    <limit effort="0" lower="0" upper="0" velocity="0"/>
  </joint>

  <joint name="$(arg robot_namespace)/dvl_joint" type="fixed">
    <origin xyz="0.805 -0.025 -0.245" rpy="3.14159 0 0" />
    <parent link="$(arg robot_namespace)/base_link"/>
    <child link="$(arg robot_namespace)/dvl_link"/>
  </joint>

  <joint name="$(arg robot_namespace)/compass_joint" type="fixed">
    <origin xyz="0 0 0" rpy="0 0 0" />
    <parent link="$(arg robot_namespace)/base_link"/>
    <child link="$(arg robot_namespace)/compass_link"/>
  </joint>

  <joint name="$(arg robot_namespace)/fls_joint" type="fixed">
    <origin xyz="0 0 0" rpy="0 0 0" />
    <parent link="$(arg robot_namespace)/base_link"/>
    <child link="$(arg robot_namespace)/fls_link"/>
  </joint>

  <joint name="$(arg robot_namespace)/imu_joint" type="fixed">
    <origin xyz="0 0 0" rpy="3.14159 0 0" />
    <parent link="$(arg robot_namespace)/base_link"/>
    <child link="$(arg robot_namespace)/imu_link"/>
  </joint>

  <joint name="$(arg robot_namespace)/pressure_joint" type="fixed">
    <origin xyz="0 0 0" rpy="0 0 0" />
    <parent link="$(arg robot_namespace)/base_link"/>
    <child link="$(arg robot_namespace)/pressure_link"/>
  </joint>

  <joint name="$(arg robot_namespace)/gps_joint" type="fixed">
    <origin xyz="0.836 0 0.44" rpy="0 0 0" />
    <parent link="$(arg robot_namespace)/base_link"/>
    <child link="$(arg robot_namespace)/gps_link"/>
  </joint>

  <joint name="$(arg robot_namespace)/mbes_joint" type="fixed">
    <origin xyz="2.523 0.0155 -0.302" rpy="3.14159 1.53589 0" />
    <parent link="$(arg robot_namespace)/base_link"/>
    <child link="$(arg robot_namespace)/mbes_link"/>
  </joint>

  <joint name="$(arg robot_namespace)/usbl_joint" type="fixed">
    <origin xyz="0.389 0.002 0.337" rpy="0 0 0" />
    <parent link="$(arg robot_namespace)/base_link"/>
    <child link="$(arg robot_namespace)/usbl_link"/>
  </joint>

</robot>
